<mujoco>
	<option timestep="0.001"  integrator="RK4">
		<flag sensornoise="enable" energy="enable" contact="enable" />
	</option>
	<asset>
		<texture type="skybox" builtin="gradient" rgb1="0.3 0.5 0.7" rgb2="0 0 0" width="512" height="3072"/>
		<texture type="2d" name="groundplane" builtin="checker" mark="edge" rgb1="0.2 0.3 0.4"
				 rgb2="0.1 0.2 0.3" markrgb="0.8 0.8 0.8" width="300" height="300"/>
		<material name="groundplane" texture="groundplane" texuniform="true" texrepeat="5 5" reflectance="0.2"/>
	</asset>

	<worldbody>
		<light pos="0 0 1"/>
		<light pos="0 -0.2 1" dir="0 0.2 -0.8" directional="true"/>
		<geom name="floor" size="0 0 0.05" type="plane" material="groundplane"/>
		<body pos="0 0 2.5" euler="0 0 0">
			<joint name="pin1" type="hinge" axis="0 -1 0" pos="0 0 -0.5"/>
			<geom type="cylinder" size="0.05 0.5" rgba="0 .9 0 1" mass="1"/>
			<body pos="0 0.1 1" euler="0 0 0">
				<joint name="pin2" type="hinge" axis="0 -1 0" pos="0 0.05 -0.5"/>
				<geom type="cylinder" size="0.05 0.5" rgba="0 0 0.9 1" mass="1"/>
			</body>
		</body>
	</worldbody>
<!--	<actuator>-->
<!--		<motor joint="pin1" name="torque" gear="1" ctrllimited="true" ctrlrange="-5 5" />-->
<!--		<position joint="pin1" name="position_servo" kp="0" />-->
<!--		<velocity joint="pin1" name="velocity_servo" kv="0" />-->
<!--	</actuator>-->
<!--	<sensor>-->
<!--		<jointpos name="position_sensor" joint="pin1" noise="0.2" />-->
<!--		<jointvel name="velocity_sensor" joint="pin1" noise="0.2" />-->
<!--	</sensor>-->
</mujoco>
